Workbook

Sheet VC shortlist
A2: India semiconductor startup investment screen
A3: As of 1 October 2026. Five diligence candidates; valuation, fund mandate and allocation availability remain unverified.
A5: Company | B5: Investment stance | C5: Why it merits diligence | D5: Buyer evidence | E5: Conditions before investment | F5: Stage / financing approach | G5: Exit route and constraint | I5: Candidate | J5: Disclosed funding (USD Mn)
A6: Vervesemi Microelectronics | B6: Prioritise commercialisation diligence | C6: Experienced analog team, fabricated product samples and several industrial use cases offer a credible route to long-lived design wins. | D6: Customer evaluation reported, but public names and committed volumes remain limited. | E6: Validate qualified SKUs, yields, gross margin after packaging/test, and two independent paying OEM design wins. | F6: Series A participation or follow-on after production qualification; avoid pricing IP-count as revenue. | G6: Product/IP sale to an analog incumbent or profitable scale-up. No exit value assumed. | I6: Vervesemi Microelectronics | J6: =Funding!C7 -> 10
A7: InCore Semiconductors | B7: Prioritise IP commercial diligence | C7: Reusable processor IP and design automation can create licensing revenue with less wafer inventory exposure than a chip-product business. | D7: Named HCL/Tessolve collaborations and partner-silicon evidence. Licence economics undisclosed. | E7: Confirm clean IP ownership, paid licences, customer tape-outs, royalty audit rights and support burden. | F7: Seed/Series A growth after paid design wins; reserve capital for engineering and international sales. | G7: Processor/IP acquisition or strategic licensing-led growth. RISC-V competition may compress prices. | I7: InCore Semiconductors | J7: =Funding!C9 -> 3
A8: FermionIC Design | B8: Prioritise customer qualification diligence | C8: Focused RF products, prototype evidence, a global foundry route and distribution channel support a differentiated niche. | D8: GF manufacturing agreement and DigiKey channel are verified relationships, not end-customer orders. | E8: Obtain customer references, signed qualification milestones, RF reliability results and volume-priced wafer/package quotes. | F8: Early growth round tied to customer qualification and first repeat shipments. | G8: Strategic acquisition by an RF/analog supplier; defence concentration may constrain growth. | I8: FermionIC Design | J8: =Funding!C8 -> 6
A9: Mindgrove Technologies | B9: Prioritise first-revenue conversion | C9: Working SecureIoT silicon, local application support and specific Indian device use cases reduce initial engineering uncertainty. | D9: Bosch/Pinetics relationships and trials are encouraging; recurring order book remains unverified. | E9: Confirm paid orders, field failure rates, firmware support cost, delivered unit margin and customer switching economics. | F9: Series A follow-on tied to first repeat commercial orders; retain funding for next chip revision. | G9: Strategic chip/OEM acquisition or a broader industrial-controller portfolio. Commodity MCU competition is a risk. | I9: Mindgrove Technologies | J9: =Funding!C6 -> 10.32
A10: Maieutic Semiconductors | B10: Prioritise paid software pilots | C10: Repeat semiconductor founders and reusable design software create a potentially efficient way to monetise scarce analog expertise. | D10: No named paying customer verified; investor quality and prior founder exit cannot substitute for software adoption. | E10: Require paid pilots, reproducible design-time savings, data-security approval and compatibility with standard EDA flows. | F10: Seed/Series A only after pilot evidence; build licence and renewal economics before scaling sales. | G10: EDA/engineering-software acquisition or independent licence growth. Incumbent bundling is the main strategic risk. | I10: Maieutic Semiconductors | J10: =Funding!C10 -> 6
A13: Exclusions and watchlist
A14: C2i | B14: Infineon acquisition announced August 2026. Treat as an exit precedent, not an available independent startup.
A15: Agnit | B15: Strong GaN research; manufacturing yield, capital intensity and pilot conversion justify a separate high-risk track.
A16: Netrasemi / BigEndian | B16: Track software maturity, camera/OEM qualification and repeat orders. Funding and tape-out alone do not establish a commercial moat.
A17: Meukron / SimYog | B17: Watch manufacturing tools and design software: capital efficiency can be attractive, but repeat sales/renewals need verification.
A18: Large fabs / OSAT projects | B18: Project capex and subsidy approvals are not VC funding. Corporate ventures and listed companies have different investment structures.
A74: Servers, data centres & storage | B74: 361 | C74: =B74/$B$81 -> 0.34315589
A75: Smartphones | B75: 192 | C75: =B75/$B$81 -> 0.18250951
A76: Industrial electronics | B76: 120 | C76: =B76/$B$81 -> 0.11406844
A77: Automotive | B77: 114 | C77: =B77/$B$81 -> 0.10836502
A78: Personal computing | B78: 112 | C78: =B78/$B$81 -> 0.10646388
A79: Consumer electronics | B79: 83 | C79: =B79/$B$81 -> 0.078897338
A80: Wired & wireless communication | B80: 70 | C80: =B80/$B$81 -> 0.066539924
B81: =SUM(B74:B80) -> 1052 | C81: =SUM(C74:C80) -> 1

Sheet Company universe
A2: Company universe and scope
A3: 120 entries: 54 company-specific profiles, the complete 103-entry April 2026 EDA roster, plus boundary/discovery entries. This is not a certified census.
A5: ID | B5: Company | C5: Product / service category | D5: Ownership / eligibility boundary | E5: State / India link | F5: Research coverage | G5: Official EDA roster no. | H5: Source IDs
A6: IN001 | B6: Mindgrove Technologies | C6: Embedded processors and edge AI | D6: Independent private company | E6: Tamil Nadu | F6: Company-specific research | G6: 54 | H6: S002, S003, S004, S005, S006, S001
A7: IN002 | B7: Vervesemi Microelectronics | C7: Analog, mixed-signal and power | D7: Independent private company | E7: Uttar Pradesh | F7: Company-specific research | G7: 91 | H7: S007, S008, S009, S010, S001
A8: IN003 | B8: FermionIC Design | C8: RF, radar and wireless chips | D8: Independent private company | E8: Karnataka | F8: Company-specific research | G8: 1 | H8: S011, S012, S013, S014, S015, S016, S001
A9: IN004 | B9: InCore Semiconductors | C9: Processor and interface IP | D9: Independent private company | E9: Tamil Nadu | F9: Company-specific research | G9: 52 | H9: S017, S018, S019, S020, S021, S001
A10: IN005 | B10: Maieutic Semiconductors | C10: Design software and EDA | D10: Independent private company | E10: Karnataka | F10: Company-specific research | G10: 41 | H10: S022, S023, S024, S025, S001
A11: IN006 | B11: C2i Semiconductors | C11: Analog, mixed-signal and power | D11: Acquisition announced; exclude from fresh VC shortlist | E11: Karnataka | F11: Company-specific research | G11: 21 | H11: S026, S027, S028, S029, S001
A12: IN007 | B12: Agnit Semiconductors | C12: Compound semiconductors and materials | D12: Independent private company | E12: Karnataka | F12: Company-specific research | H12: S030, S031, S032, S033
A13: IN008 | B13: Netrasemi | C13: Embedded processors and edge AI | D13: Independent private company | E13: Kerala | F13: Company-specific research | G13: 59 | H13: S034, S035, S036, S037, S038, S001
A14: IN009 | B14: BigEndian Semiconductors | C14: Embedded processors and edge AI | D14: Independent private company | E14: Karnataka | F14: Company-specific research | G14: 6 | H14: S039, S040, S041, S001
A15: IN010 | B15: Morphing Machines | C15: Compute accelerators | D15: Independent private company | E15: Karnataka | F15: Company-specific research | G15: 2 | H15: S042, S043, S044, S045, S001
A16: IN011 | B16: Calligo Technologies | C16: Compute accelerators | D16: Independent private company | E16: Karnataka | F16: Company-specific research | G16: 3 | H16: S046, S047, S048, S049, S050, S001
A17: IN012 | B17: HrdWyr | C17: Embedded processors and edge AI | D17: Independent private company | E17: Karnataka | F17: Company-specific research | H17: S051, S052, S053
A18: IN013 | B18: Agrani Labs | C18: Compute accelerators | D18: Independent private company | E18: Karnataka | F18: Company-specific research | H18: S054, S055
A19: IN014 | B19: Sensesemi Technologies | C19: Analog, mixed-signal and power | D19: Independent private company | E19: Karnataka | F19: Company-specific research | G19: 4 | H19: S056, S057, S001
A20: IN015 | B20: Aheesa Digital Innovations | C20: RF, radar and wireless chips | D20: Independent private company | E20: Tamil Nadu | F20: Company-specific research | G20: 51 | H20: S058, S059, S060, S061, S001
A21: IN016 | B21: Green PMU Semi | C21: Analog, mixed-signal and power | D21: Independent private company | E21: Telangana | F21: Company-specific research | G21: 63 | H21: S062, S063, S001
A22: IN017 | B22: MOSart Semi | C22: Analog, mixed-signal and power | D22: Independent private company | E22: Karnataka | F22: Company-specific research | H22: S064, S065
A23: IN018 | B23: DV2JS Innovation / 3rdiTech | C23: Sensors and MEMS | D23: Independent private company | E23: Delhi | F23: Company-specific research | G23: 97 | H23: S066, S067, S068, S001
A24: IN019 | B24: Aryabhata Circuits and Research Labs | C24: Sensors and MEMS | D24: Independent private company | E24: Karnataka | F24: Company-specific research | G24: 13 | H24: S069, S070, S001
A25: IN020 | B25: Silizium Circuits | C25: RF, radar and wireless chips | D25: Independent private company | E25: Kerala | F25: Company-specific research | G25: 60 | H25: S071, S072, S073, S001
A26: IN021 | B26: Sophrosyne Technologies | C26: Sensors and MEMS | D26: Independent private company | E26: Karnataka | F26: Company-specific research | G26: 19 | H26: S074, S075, S001
A27: IN022 | B27: MMRFIC Technology | C27: RF, radar and wireless chips | D27: Independent private company | E27: Karnataka | F27: Company-specific research | G27: 37 | H27: S076, S077, S078, S001
A28: IN023 | B28: MBit Wireless | C28: RF, radar and wireless chips | D28: Mature private company; India/overseas entity boundary needs diligence | E28: Tamil Nadu | F28: Company-specific research | G28: 58 | H28: S079, S080, S001
A29: IN024 | B29: Multi Nano Sense Technologies | C29: Sensors and MEMS | D29: Independent private company | E29: Maharashtra | F29: Company-specific research | G29: 83 | H29: S081, S082, S083, S084, S001
A30: IN025 | B30: Incise Infotech | C30: Chip-design services | D30: Established private services company | E30: Uttar Pradesh | F30: Company-specific research | G30: 92 | H30: S085, S086, S087, S001
A31: IN026 | B31: WiSig Networks | C31: RF, radar and wireless chips | D31: Independent private company | E31: Telangana | F31: Company-specific research | G31: 64 | H31: S088, S089, S090, S091, S001
A32: IN027 | B32: Aagyavision | C32: RF, radar and wireless chips | D32: Independent private company | E32: Karnataka | F32: Company-specific research | G32: 16 | H32: S092, S093, S094, S001
A33: IN028 | B33: Chipspirit Technologies | C33: Chip-design services | D33: Independent private company | E33: Karnataka | F33: Company-specific research | G33: 14 | H33: S095, S096, S097, S098, S001
A34: IN029 | B34: SandLogic Technologies | C34: Embedded processors and edge AI | D34: Independent private company | E34: Karnataka | F34: Company-specific research | G34: 12 | H34: S099, S100, S101, S102, S001
A35: IN030 | B35: SimYog Technology | C35: Design software and EDA | D35: Independent private company | E35: Karnataka | F35: Company-specific research | H35: S103, S104, S105, S106
A36: IN031 | B36: Ananant Systems | C36: RF, radar and wireless chips | D36: Independent private company | E36: Karnataka | F36: Company-specific research | G36: 40 | H36: S107, S108, S109, S001
A37: IN032 | B37: VASBEAM | C37: RF, radar and wireless chips | D37: Independent private company | E37: Maharashtra | F37: Company-specific research | G37: 79 | H37: S110, S111, S112, S001
A38: IN033 | B38: optoML | C38: Compute accelerators | D38: India-linked; Singapore parent / Indian operating entity | E38: Karnataka | F38: Company-specific research | G38: 44 | H38: S113, S114, S115, S116, S117, S001
A39: IN034 | B39: CIMware Technologies | C39: Compute systems and adjacent hardware | D39: Independent private company | E39: Karnataka | F39: Company-specific research | G39: 24 | H39: S118, S119, S001
A40: IN035 | B40: Nanojoules Semiconductors | C40: Embedded processors and edge AI | D40: Independent private company | E40: Karnataka | F40: Company-specific research | G40: 23 | H40: S120, S001
A41: IN036 | B41: Terminus Circuits | C41: Processor and interface IP | D41: Mature independent private company | E41: Karnataka | F41: Company-specific research | G41: 17 | H41: S121, S122, S001
A42: IN037 | B42: MemSmart | C42: Compute systems and adjacent hardware | D42: Independent private company | E42: Karnataka | F42: Company-specific research | G42: 9 | H42: S123, S001
...

Sheet Funding
A2: Funding totals and reconciliation
A3: Blank numeric cells mean unavailable, never zero. Totals have different disclosure completeness; do not sum the column as sector funding.
A5: ID | B5: Company | C5: Reported / reconstructed total (USD Mn) | D5: Disclosed rounds / events | E5: Last financing date | F5: Date precision | G5: Investors / financing source | H5: Basis, discrepancy and completeness | I5: Source IDs
A6: IN001 | B6: Mindgrove Technologies | C6: =SUMIF('Funding events'!$A$6:$A$37,B6,'Funding events'!$D$6:$D$37) -> 10.32 | D6: 2 | E6: 2024-12 | F6: Month | G6: Peak XV, Speciale, Whiteboard; Mela and other Series A investors | H6: USD 2.32 Mn seed + USD 8 Mn Series A; disclosed equity only. | I6: S002, S003, S004, S005, S006, S001
A7: IN002 | B7: Vervesemi Microelectronics | C7: =SUMIF('Funding events'!$A$6:$A$37,B7,'Funding events'!$D$6:$D$37) -> 10 | D7: 1 | E7: 46071 | F7: Day | G7: Ashish Kacholia, Unicorn India Ventures, Roots Ventures, Caperize, MAIQ | H7: USD 10 Mn Series A is the publicly quantified round. Earlier private capital, if any, is not reconciled. | I7: S007, S008, S009, S010, S001
A8: IN003 | B8: FermionIC Design | C8: =SUMIF('Funding events'!$A$6:$A$37,B8,'Funding events'!$D$6:$D$37) -> 6 | D8: 1 | E8: 2024 | F8: Year | G8: Ashish Kacholia and associates | H8: USD 6 Mn disclosed round; sources disagree on month (September versus December 2024), so year precision is retained. | I8: S011, S012, S013, S014, S015, S016, S001
A9: IN004 | B9: InCore Semiconductors | C9: =SUMIF('Funding events'!$A$6:$A$37,B9,'Funding events'!$D$6:$D$37) -> 3 | D9: 1 | E9: 2023-05 | F9: Month | G9: Peak XV / then Sequoia Capital India | H9: USD 3 Mn seed, rounded from database USD 2.99 Mn. No later closed round verified. | I9: S017, S018, S019, S020, S021, S001
A10: IN005 | B10: Maieutic Semiconductors | C10: =SUMIF('Funding events'!$A$6:$A$37,B10,'Funding events'!$D$6:$D$37) -> 6 | D10: 1 | E10: 45951 | F10: Day | G10: Endiya Partners, Exfinity Venture Partners, UTEC | H10: One seed round expanded from USD 4.15 Mn to USD 6 Mn. Do not add the two announcements. Last date is public expanded-round announcement. | I10: S022, S023, S024, S025, S001
A11: IN006 | B11: C2i Semiconductors | C11: =SUMIF('Funding events'!$A$6:$A$37,B11,'Funding events'!$D$6:$D$37) -> 20.7 | D11: 2 | E11: 46169 | F11: Day | G11: Yali, Lip-Bu Tan, Peak XV, TDK Ventures | H11: USD 4 Mn seed plus USD 16.7 Mn expanded Series A. February USD 15 Mn was part of the same A. Acquisition price undisclosed and excluded. | I11: S026, S027, S028, S029, S001
A12: IN007 | B12: Agnit Semiconductors | C12: =SUMIF('Funding events'!$A$6:$A$37,B12,'Funding events'!$D$6:$D$37) -> 7.4 | D12: 3 | E12: 2026-03 | F12: Month | G12: Lakshmi Narayanan / angels; 3one4, Zephyr Peacock, Shastra VC | H12: Provisional disclosed-event sum: USD 1.3 Mn angel (2021) + 3.5 Mn seed (2024) + 2.6 Mn extension (2026). Some databases show only USD 6.1 Mn/2 events; older total USD 4.87 Mn also differs. Confirm cap table; do not average different scopes. | I12: S030, S031, S032, S033
A13: IN008 | B13: Netrasemi | C13: 14.6 | D13: 3 | E13: 45862 | F13: Day | G13: Unicorn India Ventures, Zoho and earlier investors | H13: Tracxn FY25–26 reports USD 14.6 Mn. Disclosed INR events: 8.3 crore seed + 10 crore pre-A + 107 crore A = 125.3 crore. Inc42 USD 13.6 Mn/2 rounds appears to omit an earlier round. No averaging across scopes. | I13: S034, S035, S036, S037, S038, S001
A14: IN009 | B14: BigEndian Semiconductors | C14: =SUMIF('Funding events'!$A$6:$A$37,B14,'Funding events'!$D$6:$D$37) -> 9 | D14: 2 | E14: 46148 | F14: Day | G14: Vertex Ventures, IAN Alpha, IvyCap and others | H14: USD 3 Mn seed (2024) plus USD 6 Mn pre-Series A (2026). | I14: S039, S040, S041, S001
A15: IN010 | B15: Morphing Machines | C15: 14.22 | D15: 4 | E15: 46139 | F15: Day | G15: Speciale and other disclosed syndicate investors; validate full cap table | H15: Inc42 database total and event count. Latest INR 42 crore extension took Series A to INR 80 crore; do not add INR 80 crore on top of the extension. Underlying 4-event ledger not fully public. | I15: S042, S043, S044, S045, S001
A16: IN011 | B16: Calligo Technologies | C16: 2.67 | D16: 3 | E16: 45754 | F16: Day | G16: Seafund, Artha, Karnataka semiconductor fund and others | H16: Caplight total USD 2.67 Mn and Crunchbase 3 events; only USD 1.1 Mn April 2025 pre-A is directly quantified in recent reporting. Inc42 shows USD 1.1 Mn/2 events. Proposed USD 12–15 Mn 2026 raise excluded. | I16: S046, S047, S048, S049, S050, S001
A17: IN012 | B17: HrdWyr | C17: 13 | D17: 1 | E17: 46154 | F17: Day | G17: Ideaspring, Singularity, Avatar, Persistent Systems | H17: USD 13 Mn Series A; 1 quantified publicly disclosed financing event, not proof of no earlier capital. | I17: S051, S052, S053
A18: IN013 | B18: Agrani Labs | C18: 8 | D18: 1 | E18: 46050 | F18: Day | G18: Peak XV and angels | H18: USD 8 Mn seed announced January 2026. Database USD 15.3 Mn/2 events may overlap earlier closing; not added without reconciliation. Reported USD 50 Mn discussions excluded. | I18: S054, S055
A19: IN014 | B19: Sensesemi Technologies | C19: 2.7 | D19: 1 | E19: 46044 | F19: Day | G19: Piper Serica and angel/investor syndicate | H19: INR 25 crore seed, reported approximately USD 2.7 Mn; announcement-day difference across databases. | I19: S056, S057, S001
A20: IN015 | B20: Aheesa Digital Innovations | E20: 2026 | F20: Year | G20: TNIFMC / TNESSF and private investors | H20: PIB reports about INR 40 crore raised across successive rounds during 2026. TNIFMC announced INR 20 crore in March. Full round count and latest closing date remain unverified; public-fund equity is not subsidy. | I20: S058, S059, S060, S061, S001
A21: IN016 | B21: Green PMU Semi | F21: Unverified | G21: Not publicly verified | H21: No reliable company-specific total, round count or last financing date found in reviewed sources. | I21: S062, S063, S001
A22: IN017 | B22: MOSart Semi | F22: Unverified | G22: Not publicly verified | H22: No reliable company-specific total, round count or last financing date found in reviewed sources. | I22: S064, S065
A23: IN018 | B23: DV2JS Innovation / 3rdiTech | C23: 0.11 | D23: 1 | E23: 44061 | F23: Day | G23: Berkeley SkyDeck; other strategic investors undisclosed | H23: CB Insights records USD 0.11 Mn convertible note. This is a known historical event, not a complete lifetime funding total; later strategic investors reported without amounts. | I23: S066, S067, S068, S001
A24: IN019 | B24: Aryabhata Circuits and Research Labs | F24: Unverified | G24: Not publicly verified | H24: No reliable company-specific total, round count or last financing date found in reviewed sources. | I24: S069, S070, S001
A25: IN020 | B25: Silizium Circuits | F25: Unverified | G25: Not publicly verified | H25: No reliable company-specific total, round count or last financing date found in reviewed sources. | I25: S071, S072, S073, S001
A26: IN021 | B26: Sophrosyne Technologies | C26: 2 | D26: 1 | E26: 45982 | F26: Day | G26: Bluehill VC | H26: USD 2 Mn seed; database header shows 20 November while announcement/FAQ shows 21 November. | I26: S074, S075, S001
A27: IN022 | B27: MMRFIC Technology | F27: Unverified | G27: Sansera Engineering; earlier investors require reconciliation | H27: Sansera INR 20 crore investment for 22% reported in 2023-era disclosures. Lifetime equity total and complete round count not verified. | I27: S076, S077, S078, S001
A28: IN023 | B28: MBit Wireless | F28: Unverified | G28: Not publicly verified | H28: No reliable company-specific total, round count or last financing date found in reviewed sources. | I28: S079, S080, S001
A29: IN024 | B29: Multi Nano Sense Technologies | F29: Unverified | G29: Public development finance separately recorded | H29: Equity funding not reconciled. CB Insights labels historical USD 0.41 Mn as grant, while company/TDB sources indicate soft-loan support; excluded from equity. | I29: S081, S082, S083, S084, S001
A30: IN025 | B30: Incise Infotech | F30: Unverified | G30: Not publicly verified | H30: No reliable company-specific total, round count or last financing date found in reviewed sources. | I30: S085, S086, S087, S001
A31: IN026 | B31: WiSig Networks | C31: 1 | F31: Unverified | G31: Funding composition requires confirmation | H31: Bharat Innovates 2026 profile reports USD 1 Mn funding; equity-versus-grant split, round count and latest financing date not disclosed. | I31: S088, S089, S090, S091, S001
A32: IN027 | B32: Aagyavision | F32: Unverified | G32: Not publicly verified | H32: No reliable company-specific total, round count or last financing date found in reviewed sources. | I32: S092, S093, S094, S001
A33: IN028 | B33: Chipspirit Technologies | D33: 1 | E33: 2021 | F33: Year | G33: SFAL / incubator support; instrument classification to confirm | H33: Crunchbase records one financing round; amount undisclosed. CB Insights gives January 2021 but precise date is not independently confirmed. | I33: S095, S096, S097, S098, S001
A34: IN029 | B34: SandLogic Technologies | C34: 4 | E34: 2022-02 | F34: Month | G34: Texas-based HNIs; full investor/instrument ledger to verify | H34: USD 4 Mn historical funding reported. Crunchbase counts 3 events but full instrument ledger is inaccessible. USD 30–40 Mn 2025 financing discussions are not a closed round. | I34: S099, S100, S101, S102, S001
A35: IN030 | B35: SimYog Technology | D35: 3 | E35: 45274 | F35: Day | G35: Mela Ventures, 1Crowd, Ideaspring, Bosch | H35: Crunchbase reports 3 rounds. INR 20 crore Series A (about USD 2.4 Mn) in December 2023 and INR 6.3 crore earlier round reported. Complete total not reconciled. | I35: S103, S104, S105, S106
A36: IN031 | B36: Ananant Systems | C36: 3 | F36: Unverified | G36: SIIC ecosystem and undisclosed investors | H36: Bharat Innovates 2026 profile reports approximately USD 3 Mn. Complete round dates/count undisclosed. September USD 5 Mn proposed government/RDI raise excluded. | I36: S107, S108, S109, S001
A37: IN032 | B37: VASBEAM | F37: Unverified | G37: Not publicly verified | H37: No reliable company-specific total, round count or last financing date found in reviewed sources. | I37: S110, S111, S112, S001
A38: IN033 | B38: optoML | C38: 1.8 | D38: 1 | E38: 46077 | F38: Day | G38: Bluehill VC, A99 | H38: USD 1.8 Mn pre-Series A/seed (stage terminology differs by source). | I38: S113, S114, S115, S116, S117, S001
A39: IN034 | B39: CIMware Technologies | C39: 2.3 | D39: 1 | E39: 45840 | F39: Day | G39: Transition VC | H39: USD 2.3 Mn pre-Series A / first disclosed equity round. | I39: S118, S119, S001
A40: IN035 | B40: Nanojoules Semiconductors | F40: Unverified | G40: Not publicly verified | H40: No reliable company-specific total, round count or last financing date found in reviewed sources. | I40: S120, S001
A41: IN036 | B41: Terminus Circuits | F41: Unverified | G41: Not publicly verified | H41: No reliable company-specific total, round count or last financing date found in reviewed sources. | I41: S121, S122, S001
A42: IN037 | B42: MemSmart | F42: Unverified | G42: Not publicly verified | H42: No reliable company-specific total, round count or last financing date found in reviewed sources. | I42: S123, S001
...

Sheet Funding events
A2: Disclosed financing events
A3: Incremental extensions are separated from full round sizes. Incomplete histories are explicitly marked in Funding; dates reflect announcement precision.
A5: Company | B5: Round / event | C5: Announcement / closing date | D5: Incremental USD Mn | E5: Original INR crore | F5: Instrument / classification | G5: Reconciliation note | H5: Source IDs
A6: Mindgrove Technologies | B6: Seed | C6: 2023-02 | D6: 2.32 | F6: Equity | G6: Disclosed seed round. | H6: S002, S003, S004, S005, S006, S001
A7: Mindgrove Technologies | B7: Series A | C7: 2024-12 | D7: 8 | F7: Equity | G7: Separate financing round. | H7: S002, S003, S004, S005, S006, S001
A8: Vervesemi Microelectronics | B8: Series A | C8: 46071 | D8: 10 | F8: Equity | G8: Earlier funding not reconciled. | H8: S007, S008, S009, S010, S001
A9: FermionIC Design | B9: Disclosed round | C9: 2024 | D9: 6 | F9: Equity | G9: Month conflicts between sources; year only. | H9: S011, S012, S013, S014, S015, S016, S001
A10: InCore Semiconductors | B10: Seed | C10: 2023-05 | D10: 3 | F10: Equity | G10: USD 2.99 Mn database figure rounded to USD 3 Mn. | H10: S017, S018, S019, S020, S021, S001
A11: Maieutic Semiconductors | B11: Seed initial close | C11: 45841 | D11: 4.15 | F11: Equity | G11: Part of the seed round later expanded to USD 6 Mn. | H11: S022, S023, S024, S025, S001
A12: Maieutic Semiconductors | B12: Seed extension | C12: 45951 | D12: =6-4.15 -> 1.85 | F12: Equity extension | G12: Incremental amount derived as 6.00 minus 4.15; not a second independent seed round. | H12: S022, S023, S024, S025, S001
A13: C2i Semiconductors | B13: Seed | C13: 45604 | D13: 4 | F13: Equity | G13: Announcement in November; investor timeline says October close. | H13: S026, S027, S028, S029, S001
A14: C2i Semiconductors | B14: Series A initial close | C14: 46069 | D14: 15 | F14: Equity | G14: Part of expanded Series A. | H14: S026, S027, S028, S029, S001
A15: C2i Semiconductors | B15: Series A extension | C15: 46169 | D15: =16.7-15 -> 1.7 | F15: Equity extension | G15: Incremental amount derived as 16.70 minus 15.00. Acquisition consideration excluded. | H15: S026, S027, S028, S029, S001
A16: Agnit Semiconductors | B16: Angel | C16: 2021 | D16: 1.3 | F16: Equity — historical report | G16: Older event omitted from some database totals; cap-table confirmation required. | H16: S030, S031, S032, S033
A17: Agnit Semiconductors | B17: Seed | C17: 2024-10 | D17: 3.5 | F17: Equity | G17: USD 3.5 Mn reported. | H17: S030, S031, S032, S033
A18: Agnit Semiconductors | B18: Seed extension | C18: 2026-03 | D18: 2.6 | F18: Equity extension | G18: 3 funding events including 2021 angel, not necessarily 3 priced institutional rounds. | H18: S030, S031, S032, S033
A19: Netrasemi | B19: Seed | E19: 8.3 | F19: Equity — reported | G19: Date not verified. INR is source currency. | H19: S034, S035, S036, S037, S038, S001
A20: Netrasemi | B20: Pre-Series A | C20: 2024-12 | E20: 10 | F20: Equity | G20: Do not convert each event using an invented current FX rate. | H20: S034, S035, S036, S037, S038, S001
A21: Netrasemi | B21: Series A | C21: 45862 | E21: 107 | F21: Equity | G21: USD total in Funding tab uses reported Tracxn total, not a conversion of this row. | H21: S034, S035, S036, S037, S038, S001
A22: BigEndian Semiconductors | B22: Seed | C22: 2024 | D22: 3 | F22: Equity | G22: USD 3 Mn. | H22: S039, S040, S041, S001
A23: BigEndian Semiconductors | B23: Pre-Series A | C23: 46148 | D23: 6 | F23: Equity | G23: USD 6 Mn. | H23: S039, S040, S041, S001
A24: HrdWyr | B24: Series A | C24: 46154 | D24: 13 | F24: Disclosed private financing | G24: See Funding tab for completeness and instrument limitations. | H24: S051, S052, S053
A25: Agrani Labs | B25: Seed announcement | C25: 46050 | D25: 8 | F25: Disclosed private financing | G25: See Funding tab for completeness and instrument limitations. | H25: S054, S055
A26: Sophrosyne Technologies | B26: Seed | C26: 45982 | D26: 2 | F26: Disclosed private financing | G26: See Funding tab for completeness and instrument limitations. | H26: S074, S075, S001
A27: optoML | B27: Pre-Series A / seed | C27: 46077 | D27: 1.8 | F27: Disclosed private financing | G27: See Funding tab for completeness and instrument limitations. | H27: S113, S114, S115, S116, S117, S001
A28: CIMware Technologies | B28: Pre-Series A | C28: 45840 | D28: 2.3 | F28: Disclosed private financing | G28: See Funding tab for completeness and instrument limitations. | H28: S118, S119, S001
A29: Quanfluence | B29: Seed | C29: 45644 | D29: 2 | F29: Disclosed private financing | G29: See Funding tab for completeness and instrument limitations. | H29: S124, S125, S126, S001
A30: Tattvam AI | B30: Pre-seed | C30: 46078 | D30: 1.7 | F30: Disclosed private financing | G30: See Funding tab for completeness and instrument limitations. | H30: S151
A31: Ceremorphic | B31: Founder-financed Series A | C31: 44585 | D31: 50 | F31: Disclosed private financing | G31: See Funding tab for completeness and instrument limitations. | H31: S148, S149, S150
A32: Calligo Technologies | B32: Pre-Series A | C32: 45754 | D32: 1.1 | F32: Disclosed private financing | G32: See Funding tab for completeness and instrument limitations. | H32: S046, S047, S048, S049, S050, S001
A33: SandLogic Technologies | B33: Disclosed funding | C33: 2022-02 | D33: 4 | F33: Disclosed private financing | G33: See Funding tab for completeness and instrument limitations. | H33: S099, S100, S101, S102, S001
A34: DV2JS Innovation / 3rdiTech | B34: Convertible note | C34: 44061 | D34: 0.11 | F34: Disclosed private financing | G34: See Funding tab for completeness and instrument limitations. | H34: S066, S067, S068, S001
A35: Sensesemi Technologies | B35: Seed | C35: 46044 | D35: 2.7 | E35: 25 | F35: Equity | G35: USD approximation as reported; original INR 25 crore. | H35: S056, S057, S001
A36: Aheesa Digital Innovations | B36: TNIFMC agreement | C36: 46093 | E36: 20 | F36: Public-fund equity | G36: Part of about INR 40 crore cumulative 2026 funding reported by PIB. Remaining capital has no separately verified event date. Not a subsidy. | H36: S058, S059, S060, S061, S001
A37: SimYog Technology | B37: Series A | C37: 45274 | D37: 2.4 | E37: 20 | F37: Equity | G37: Latest disclosed round only; earlier rounds omitted here where exact dates are unresolved. | H37: S103, S104, S105, S106

Sheet Founders
A2: Founders and relevant experience
A3: Founder status is distinguished from CEO, adviser and director status. Unverified full founding teams are flagged.
A5: ID | B5: Company | C5: Founders / role qualification | D5: Relevant background | E5: Repeat founder / professor / employer flags | F5: Source IDs
A6: IN001 | B6: Mindgrove Technologies | C6: Shashwath T R; Sharan Srinivas J (also known as Sharan Jagathrakshakan) | D6: Engineering founders with embedded-computing experience. IIT Madras incubation and SHAKTI ecosystem. Do not confuse Sharan with the Perplexity founder. | E6: Technical founders; IIT Madras ecosystem | F6: S002, S003, S004, S005, S006, S001
A7: IN002 | B7: Vervesemi Microelectronics | C7: Rakesh Malik; Pratap Narayan Singh | D7: Malik previously held senior roles at STMicroelectronics. Singh worked on converters at STMicroelectronics and on audio/power at Wolfson. Their experience is directly relevant to precision analog design. | E7: Ex-global semiconductor employees; experienced founders | F7: S007, S008, S009, S010, S001
A8: IN003 | B8: FermionIC Design | C8: Gautam Kumar Singh; Prasun Bhattacharyya; Abhra Bagchi; Shabaaz Syed | D8: Experienced RF, mixed-signal and chip-integration team. Individual prior employers and full employment chronology require confirmation. | E8: Experienced semiconductor founders | F8: S011, S012, S013, S014, S015, S016, S001
A9: IN004 | B9: InCore Semiconductors | C9: G S Madhusudan; Neel Gala; Arjun Menon; Gautam Doshi | D9: Team emerged from the IIT Madras SHAKTI processor ecosystem. Madhusudan combines industry and systems experience; Gala and Menon bring processor research/design expertise. Professor V. Kamakoti is an ecosystem mentor, not automatically a founder. | E9: Research-to-commercialisation; experienced processor team | F9: S017, S018, S019, S020, S021, S001
A10: IN005 | B10: Maieutic Semiconductors | C10: Gireesh Rajendran; Ashish Lachhwani; Rakesh Kumar; Krishna Sankar | D10: Founding team includes Steradian entrepreneurs whose radar business was acquired by Renesas in 2022, alongside analog-design expertise. Prior exit is evidence of execution, not a promised repeat outcome. | E10: Repeat founders; prior semiconductor exit | F10: S022, S023, S024, S025, S001
A11: IN006 | B11: C2i Semiconductors | C11: Ram Anant; Preetam Tadeparthy; Vikram Gakhar; B S Dattatreya. Reporting also identifies Harsha S B and Muthusubramanian N V as co-founders. | D11: Former Texas Instruments power and analog executives. Founders’ experience spans control, mixed-signal and power design. | E11: Ex-Texas Instruments; announced strategic exit | F11: S026, S027, S028, S029, S001
A12: IN007 | B12: Agnit Semiconductors | C12: Hareesh Chandrasekar; Madhusudan Atre; Mayank Shrivastava; Digbijoy Nath; Muralidharan Rangarajan; Shankar Kumar Selvaraja; Srinivasan Raghavan | D12: IISc faculty/research spin-out supported by experienced semiconductor leadership. Combines device/materials research with commercialisation expertise. | E12: Professor founders; research spin-out; industry veteran | F12: S030, S031, S032, S033
A13: IN008 | B13: Netrasemi | C13: Jyothis Indirabhai; Sreejith Varma; Deepa Geetha | D13: Experienced semiconductor team based in Thiruvananthapuram. Detailed individual prior-employer chronology remains to be independently checked. | E13: Experienced semiconductor founders | F13: S034, S035, S036, S037, S038, S001
A14: IN009 | B14: BigEndian Semiconductors | C14: Sunil Kumar; Renuka Prasad; Harpreet Wadhawan; Dinesh Annayya; Kanagaraju Ponnusamy; Jansen Cheng (reported founding team) | D14: Team experience includes Arm, Intel and Broadcom. Verify each founder’s role and IP-assignment history. | E14: Ex-global semiconductor team | F14: S039, S040, S041, S001
A15: IN010 | B15: Morphing Machines | C15: S K Nandy; Ranjani Narayan; Deepak Shapeti (current company founding/leadership team) | D15: IISc research origins with academic and processor-architecture expertise. Deepak Shapeti joined the commercial leadership later than the original 2005 foundation. | E15: Professor/research founders; long development history | F15: S042, S043, S044, S045, S001
A16: IN011 | B16: Calligo Technologies | C16: Anantha Padmanabha Kinnal; Rajaraman Subramanian | D16: Experienced computing/semiconductor entrepreneurs. Detailed prior employment requires confirmation. | E16: Experienced technical founders | F16: S046, S047, S048, S049, S050, S001
... A125: IN120 | B125: CraftifAI Technologies | C125: Not publicly verified | D125: Not publicly verified | E125: Not publicly verified | F125: S174

Sheet Products and readiness
A2: Products, Indian applications and readiness
A3: A tape-out sends a design for manufacture. Working samples, customer qualification and repeat volume shipments are separate milestones.
A5: ID | B5: Company | C5: Product / service detail | D5: Application in the Indian economy | E5: Latest evidenced readiness | F5: Readiness category | G5: Source IDs
A6: IN001 | B6: Mindgrove Technologies | C6: SecureIoT S2401 combines a RISC-V processor with memory, security and peripheral functions. Evaluation boards support firmware development. Vision-series chips target camera and other on-device visual processing. | D6: Local controllers for smart meters, access control, industrial devices and cameras can reduce dependence on imported controllers and improve local technical support. | E6: SecureIoT first silicon was demonstrated in May 2024; evaluation board launched in March 2025. September 2026 reporting describes customer trials and first revenue expected in FY27. Later-2026 roadmap entries are targets, not proof of shipment. | F6: Working silicon / customer trials | G6: S002, S003, S004, S005, S006, S001
A7: IN002 | B7: Vervesemi Microelectronics | C7: Analog and mixed-signal IP and ICs for accurate measurement, motor control, energy metering and power conversion. The DLI programme supports a mixed-signal motor-control microcontroller. | D7: More efficient fans and appliances, accurate smart meters, industrial motor drives and reliable aerospace instrumentation. | E7: August 2026 PIB update confirms first-pass BLDC-controller silicon using InCore IP and a motor-driver chip. Earlier fabricated analog products were under evaluation. Qualified volume shipments are not verified. | F7: Fabricated silicon / evaluation | G7: S007, S008, S009, S010, S001
A8: IN003 | B8: FermionIC Design | C8: Radio-frequency chips and interface IP. DLI project is an 8–12 GHz four-channel gain/phase-control chip for electronically steered antenna arrays. Beamformer and front-end products support radar and satellite links. | D8: Local radar electronics, defence communications, satellite terminals and telecom equipment can substitute imported RF components. | E8: Company demonstrated a prototype antenna tile using its own chips in early 2026. GlobalFoundries manufacturing partnership announced June 2026. Mass-production volumes are not publicly verified. | F8: Prototype / foundry partnership | G8: S011, S012, S013, S014, S015, S016, S001
A9: IN004 | B9: InCore Semiconductors | C9: Configurable RISC-V processor IP and automated system-on-chip generation. Customers license reusable processor designs and integrate them into their own chips rather than buying a general-purpose InCore chip. | D9: Domestic IP ownership for metering, cameras, industrial controllers and future custom chips. Enables Indian companies to design products without building a CPU team from scratch. | E9: Company reports a six-core test chip and silicon validation of its SoC generator. September 2026 company material shows partners’ taped-out chips using InCore IP. This supports IP validation, not a disclosed royalty run rate. | F9: Silicon-validated IP | G9: S017, S018, S019, S020, S021, S001
A10: IN005 | B10: Maieutic Semiconductors | C10: AI-assisted analog and mixed-signal circuit-design software. Engineers can use an assistant to explore designs, review circuits and reduce repetitive development work. | D10: Can improve productivity of India’s chip-design teams and help smaller fabless companies cope with scarce experienced analog engineers. | E10: Product development and planned rollout reported. Independent production-workflow benchmarks and paying-customer deployment evidence were not verified. A proprietary chip tape-out is not the right readiness test for this software. | F10: Software development / commercial validation pending | G10: S022, S023, S024, S025, S001
A11: IN006 | B11: C2i Semiconductors | C11: Manas digital multiphase controller and Sarayu smart power stage. Software-defined voltage regulation delivers power close to AI processors. | D11: Supports efficient AI servers and data-centre power systems. Indian adoption depends on server-design qualification rather than data-centre construction alone. | E11: First designs sent to foundries in 2026 and smart-power-stage tape-out announced in May. Independent mass-production qualification not verified. | F11: Tape-out / strategic acquisition | G11: S026, S027, S028, S029, S001
A12: IN007 | B12: Agnit Semiconductors | C12: Gallium nitride (GaN) materials, RF devices and related process technology. Focus includes high-frequency/high-power chips for communications and defence. | D12: Local RF supply for radar, telecom and strategic electronics. Power-device applications are a longer-term option and should not be confused with qualified charger or EV products. | E12: Pilot projects and process development reported. March 2026 reporting targeted commercial shipments for July 2027; five pilots reported in August 2026. Do not treat target volume as actual sales. | F12: Pilot / manufacturing scale-up | G12: S030, S031, S032, S033
A13: IN008 | B13: Netrasemi | C13: Edge-AI system-on-chips for cameras, robotics and industrial devices. A2000 and R1000 product programmes combine local AI, video processing and connectivity. | D13: Processes camera and sensor data locally, reducing network dependence and supporting surveillance, automation and robotics. | E13: August 2026 PIB update confirms successful testing of a 12 nm vision SoC. Customer trials were reported in May. Commercial volume production remains unverified. | F13: First chip / trials; next chip taped out | G13: S034, S035, S036, S037, S038, S001
A14: IN009 | B14: BigEndian Semiconductors | C14: Secure video-processing and edge-AI chips for surveillance cameras and related connected equipment. | D14: Supports indigenous camera electronics and local control over security-sensitive silicon and firmware. | E14: Investors report successful tape-out and progression from test silicon towards production-ready devices in 2026. Production qualification not independently confirmed. | F14: Tape-out / test silicon | G14: S039, S040, S041, S001
A15: IN010 | B15: Morphing Machines | C15: REDEFINE reconfigurable many-core compute architecture, processor IP and accelerator-card ecosystem. Aims to adapt hardware resources to changing compute workloads. | D15: Potential acceleration for industrial, defence and scientific workloads, subject to real application benchmarks and software portability. | E15: Company roadmap targeted a test chip in Q3 2026. Verified completed silicon and volume deployment not located; elapsed target date is not completion. | F15: Development / silicon confirmation pending | G15: S042, S043, S044, S045, S001
A16: IN011 | B16: Calligo Technologies | C16: TUNGA RISC-V processor with POSIT arithmetic and accelerator-card/software stack. POSIT is an alternative numeric representation intended to improve computing efficiency. | D16: Scientific computing, engineering simulations and specialised AI workloads; value must be demonstrated against current CPU/GPU systems on complete applications. | E16: TUNGA first-generation chip and early-customer testing reported. Independent deployment volumes and benchmark reproducibility not verified. | F16: Working chip / early testing | G16: S046, S047, S048, S049, S050, S001
... A125: IN120 | B125: CraftifAI Technologies | C125: Named in September 2026 SEMICON startup competition coverage. Detailed product specification not verified. | D125: Not publicly verified | E125: Award/selection does not establish deployment readiness. | F125: Not established | G125: S174

Sheet Customers and alliances
A2: Customer evidence, alliances and potential beneficiaries
A3: Confirmed relationship descriptions and analyst-proposed beneficiaries are kept separate. Potential beneficiary lists are not customer lists.
A5: ID | B5: Company | C5: Target customer segment | D5: Named customers / evidence limits | E5: Commercial conviction / next test | F5: Strategic alliances and their limits | G5: Potential large / listed Indian beneficiaries (inference) | H5: Indian fab / OSAT / compound-fab fit (inference) | I5: Source IDs
A6: IN001 | B6: Mindgrove Technologies | C6: Device manufacturers, meter makers, camera and industrial-equipment designers. | D6: Bosch BGSW alliance and Pinetics integration agreement are named commercial-development signals. Metering, biometric and CCTV trials are reported. Recurring volume orders remain unverified. PRAMA India is a further named camera-development partner. | E6: Conditional: working silicon and integration partners reduce engineering risk. Require purchase orders, qualification reports and cash collections before underwriting a volume ramp. | F6: Bosch BGSW MoU / startup alliance; Pinetics integration. Neither establishes a guaranteed minimum purchase. PRAMA India agreement explores Vision SoC use in CCTV cameras; not a volume purchase commitment. | G6: Genus Power, HPL Electric, Dixon, Kaynes Technology and BEL are prospective adopters, not confirmed customers. | H6: Potential packaging/test demand for Kaynes, CG Semi, Suchi or Tata’s packaging business after package qualification. A future Tata silicon-fab port needs compatible node, process IP and redesign; no automatic fit. | I6: S002, S003, S004, S005, S006, S001
A7: IN002 | B7: Vervesemi Microelectronics | C7: Industrial and appliance OEMs, meter manufacturers, space/defence electronics suppliers and chip designers licensing analog IP. | D7: An identified but unnamed space customer was reported by PIB. Public customer names, committed quantities and recurring chip revenue are not established. | E7: Promising product breadth and experienced analog team. Validate which ICs are actually qualified and revenue-producing rather than counting IP blocks as commercial chips. | F7: UMC and TSMC process use is reported by PIB. Samsung SAFE IP participation is reported in Bharat Innovates material; it is an ecosystem relationship, not an offtake contract. InCore processor IP used in BLDC controller, confirmed by PIB in August 2026. | G7: Havells, Crompton, Genus Power, HPL Electric, BEL, HAL and Dixon are prospective adopters. | H7: Potential packaging/test demand for Kaynes, CG Semi, Suchi or Tata’s packaging business after package qualification. A future Tata silicon-fab port needs compatible node, process IP and redesign; no automatic fit. | I7: S007, S008, S009, S010, S001
A8: IN003 | B8: FermionIC Design | C8: Radar, aerospace, satellite-communication and telecom equipment manufacturers; chip-design customers for interface IP. | D8: Company claims Indian and overseas OEM engagements. DigiKey supplier presence provides a named sales channel. No named recurring-volume purchase agreement verified. | E8: Stronger production-route evidence than a design-only project. Diligence must establish qualification, unit economics, order backlog and whether RF components meet defence reliability requirements. | F8: Commercial manufacturing partnership with GlobalFoundries announced 11 June 2026; DigiKey distribution. Qualcomm mentorship is not a customer order. | G8: BEL, HAL, Data Patterns, Astra Microwave, Paras Defence and Tejas Networks are prospective adopters. | H8: Packaging/test opportunity for Kaynes, CG Semi or specialist OSATs, subject to RF process/package qualification. SiGe/GaN designs cannot simply transfer into a standard CMOS fab. | I8: S011, S012, S013, S014, S015, S016, S001
A9: IN004 | B9: InCore Semiconductors | C9: Fabless chip companies, ASIC design houses and OEMs developing custom silicon. | D9: Vervesemi controller silicon uses InCore IP, confirmed by PIB in August 2026. HCL/Tessolve collaborations are also named. Licence fees and recurring royalties remain undisclosed. | E9: Attractive capital efficiency because IP can be licensed repeatedly. Confirm ownership of university-derived IP, paid licences and royalty-bearing designs. | F9: HCL and Tessolve solution collaborations; RISC-V ecosystem. An open instruction-set standard is not an exclusive global-chipmaker alliance. | G9: HCLTech, Cyient, MosChip, Tata Elxsi and L&T Semiconductor Technologies could use processor IP in customer or internal designs. | H9: Indirect enabler: supports customer designs/IP rather than directly filling wafer capacity. Potential users include MosChip, Cyient, HCLTech and L&T Semiconductor Technologies. | I9: S017, S018, S019, S020, S021, S001
A10: IN005 | B10: Maieutic Semiconductors | C10: Analog chip designers, semiconductor product companies and design-services teams. | D10: No named paying customers or recurring software revenue verified. | E10: Founder execution history and reusable software are attractive. Investment depends on paid pilots, measurable engineer time savings and integration with incumbent EDA tools. | F10: UTEC, Endiya and Exfinity are financial investors. The founders’ former Renesas exit is not a current Maieutic–Renesas partnership. | G10: MosChip, Cyient, HCLTech, L&T Semiconductor Technologies and Indian analog design centres are prospective users. | H10: Indirect enabler: supports customer designs/IP rather than directly filling wafer capacity. Potential users include MosChip, Cyient, HCLTech and L&T Semiconductor Technologies. | I10: S022, S023, S024, S025, S001
A11: IN006 | B11: C2i Semiconductors | C11: Global server manufacturers, power-module suppliers and AI infrastructure designers. | D11: No named committed-volume buyer verified before acquisition. Infineon supplies strategic validation and potential access to customers; it is an acquirer, not evidence of existing customer revenue. | E11: Useful exit precedent, but unavailable as a normal independent VC candidate after acquisition agreement. | F11: TDK Ventures strategic investment; Tower Semiconductor / GlobalFoundries fabrication routes. Infineon announced acquisition on 24 August 2026; release expected Q3 closing, separate closing confirmation not located. | G11: Netweb Technologies and Indian server/power-system manufacturers are prospective downstream beneficiaries. Tata Communications and Reliance data centres could benefit indirectly. | H11: Potential packaging/test demand for Kaynes, CG Semi, Suchi or Tata’s packaging business after package qualification. A future Tata silicon-fab port needs compatible node, process IP and redesign; no automatic fit. | I11: S026, S027, S028, S029, S001
A12: IN007 | B12: Agnit Semiconductors | C12: Defence and telecom equipment manufacturers, RF module companies and wafer/device customers. | D12: Five pilots reported, but counterparties and binding volume orders not publicly verified. | E12: Strong differentiated science; higher process, yield and capital risk. Require reproducible yields, paid pilot conversion and a funding plan that does not depend on an unapproved fab subsidy. | F12: IISc GaN ecosystem; iDEX development relationship. No purchase commitment from a global semiconductor giant verified. | G12: BEL, Astra Microwave, Data Patterns and Tejas Networks are prospective users; SiCSem and RIR are adjacent compound-semiconductor companies, not interchangeable GaN foundries. | H12: SiCSem (Archean) and RIR are relevant compound-power ecosystem peers. GaN and SiC processes are different; no automatic foundry compatibility or customer relationship. | I12: S030, S031, S032, S033
A13: IN008 | B13: Netrasemi | C13: Camera makers, robotics companies and industrial/consumer device OEMs. | D13: Customer trials reported; Zoho is an investor and cannot be treated as guaranteed offtake. Named volume customers not verified. | E13: Meaningful capital and product progress, but commercial qualification and software adoption remain key risks. | F13: TSMC manufacturing/process relationship; Zoho strategic investment. No guaranteed purchase volumes verified. | G13: Dixon, Kaynes Technology, BEL, Tata Elxsi and industrial OEMs are prospective adopters. | H13: Potential packaging/test demand for Kaynes, CG Semi, Suchi or Tata’s packaging business after package qualification. A future Tata silicon-fab port needs compatible node, process IP and redesign; no automatic fit. | I13: S034, S035, S036, S037, S038, S001
A14: IN009 | B14: BigEndian Semiconductors | C14: Surveillance camera brands, camera design manufacturers and security-equipment OEMs. | D14: Unnamed OEM relationships reported by investors. No named firm volume order verified. | E14: Clear initial use case, but needs competitive image quality, software compatibility and OEM qualification against entrenched suppliers. | F14: Not publicly verified | G14: Dixon, Kaynes, BEL and Indian surveillance manufacturers are prospective adopters. | H14: Potential packaging/test demand for Kaynes, CG Semi, Suchi or Tata’s packaging business after package qualification. A future Tata silicon-fab port needs compatible node, process IP and redesign; no automatic fit. | I14: S039, S040, S041, S001
A15: IN010 | B15: Morphing Machines | C15: Compute OEMs, defence research users, chip companies and specialised high-performance computing customers. | D15: Research and proof-of-concept engagements reported; named recurring commercial buyers not verified. | E15: Scientific differentiation is plausible, but long development history and software ecosystem make commercial validation essential. | F15: Not publicly verified | G15: BEL, HAL, Netweb, HCLTech and Cyient are prospective adopters/integration channels. | H15: Potential packaging/test demand for Kaynes, CG Semi, Suchi or Tata’s packaging business after package qualification. A future Tata silicon-fab port needs compatible node, process IP and redesign; no automatic fit. | I15: S042, S043, S044, S045, S001
A16: IN011 | B16: Calligo Technologies | C16: HPC operators, research institutions, server/accelerator OEMs and scientific-computing users. | D16: Early evaluations reported; customer identities and binding backlog not verified. | E16: Working silicon helps. Unusual arithmetic creates a software-porting and customer-adoption hurdle. | F16: Not publicly verified | G16: Netweb Technologies, HCLTech, BEL and Indian research-compute suppliers are prospective adopters. | H16: Potential packaging/test demand for Kaynes, CG Semi, Suchi or Tata’s packaging business after package qualification. A future Tata silicon-fab port needs compatible node, process IP and redesign; no automatic fit. | I16: S046, S047, S048, S049, S050, S001
... A22: IN017 | B22: MOSart Semi | C22: Battery-pack makers, EV OEMs and energy-storage system manufacturers. | D22: No named purchase order or recurring product revenue verified. | E22: Battery management has clear demand, but automotive qualification and safety requirements create long sales cycles. | F22: Not publicly verified | G22: Exide Industries, Amara Raja Energy & Mobility, Tata Motors, M&M and TVS Motor are prospective users. | H22: Potential packaging/test demand for Kaynes, CG Semi, Suchi or Tata’s packaging business after package qualification. A future Tata silicon-fab port needs compatible node, process IP and redesign; no automatic fit. | I22: S064, S065
A23: IN018 | B23: DV2JS Innovation / 3rdiTech | C23: Defence/imaging equipment OEMs and specialist camera manufacturers. | D23: Strategic-government engagement and consortium MoUs exist; public recurring orders not verified. | F23: 2025 MoU with Kaynes Semicon, SPARSHIQ and consortium partners. Indo-US Bharat Semi/3rdiTech fab collaboration announced in 2024 is not proof of an operational fab. | G23: BEL, HAL, Data Patterns and Kaynes are prospective users/packaging participants; Kaynes MoU is confirmed at consortium level. | H23: Potential packaging/test demand for Kaynes, CG Semi, Suchi or Tata’s packaging business after package qualification. A future Tata silicon-fab port needs compatible node, process IP and redesign; no automatic fit. | I23: S066, S067, S068, S001
A24: IN019 | B24: Aryabhata Circuits and Research Labs | C24: Tyre manufacturers, automotive electronics suppliers, fleet-system providers and vehicle OEMs. | D24: No named purchase order or recurring product revenue verified. | E24: Specific automotive pain point; automotive reliability, tyre integration and a paying tier-one partner are gating items. | F24: Not publicly verified | G24: MRF, Apollo Tyres, CEAT, JK Tyre, Tata Motors and M&M are prospective users. | H24: Potential packaging/test demand for Kaynes, CG Semi, Suchi or Tata’s packaging business after package qualification. A future Tata silicon-fab port needs compatible node, process IP and redesign; no automatic fit. | I24: S069, S070, S001
A25: IN020 | B25: Silizium Circuits | C25: Telecom, navigation, satellite-equipment and industrial-IoT manufacturers. | D25: C-DOT is a named development counterparty; this is stronger than an unnamed pipeline but not equivalent to commercial chip volume. | F25: C-DOT TTDF contract; IIT Kanpur research collaboration; NXP/FabCI accelerator association is not an offtake agreement. | G25: BEL, Tejas, HFCL, Data Patterns and navigation-equipment OEMs are prospective adopters. | H25: Packaging/test opportunity for Kaynes, CG Semi or specialist OSATs, subject to RF process/package qualification. SiGe/GaN designs cannot simply transfer into a standard CMOS fab. | I25: S071, S072, S073, S001
A26: IN021 | B26: Sophrosyne Technologies | C26: Wearable brands, medical-device OEMs and health-monitoring equipment suppliers. | D26: No named recurring-volume customer verified. | E26: Healthcare sensing is a useful niche, but chip performance and medical-system validation must be distinguished. | F26: Not publicly verified | G26: Dixon, Syrma SGS and Indian medical-electronics manufacturers are prospective users. | H26: Potential packaging/test demand for Kaynes, CG Semi, Suchi or Tata’s packaging business after package qualification. A future Tata silicon-fab port needs compatible node, process IP and redesign; no automatic fit. | I26: S074, S075, S001
A27: IN022 | B27: MMRFIC Technology | C27: Defence, aerospace, space and telecom equipment makers. | D27: Sansera Engineering’s strategic investment is a named relationship. Product purchase commitments not verified. | F27: Sansera Engineering strategic investment; not a global-semiconductor-giant purchase agreement. | G27: Sansera is a strategic investor. BEL, Astra Microwave and Data Patterns are prospective RF-system adopters. | H27: Packaging/test opportunity for Kaynes, CG Semi or specialist OSATs, subject to RF process/package qualification. SiGe/GaN designs cannot simply transfer into a standard CMOS fab. | I27: S076, S077, S078, S001
A28: IN023 | B28: MBit Wireless | C28: Cellular-module suppliers, IoT device makers and telecom-equipment OEMs. | D28: No named purchase order or recurring product revenue verified. | E28: Confirm IP ownership across Indian/US entities, modem certification and module-maker design wins. | F28: Not publicly verified | G28: Genus Power, HPL Electric, Tejas, HFCL and ITI are prospective adopters. | H28: Packaging/test opportunity for Kaynes, CG Semi or specialist OSATs, subject to RF process/package qualification. SiGe/GaN designs cannot simply transfer into a standard CMOS fab. | I28: S079, S080, S001
A29: IN024 | B29: Multi Nano Sense Technologies | C29: Hydrogen producers, industrial plants, safety-equipment OEMs and gas-sensor integrators. | D29: Company lists clientele and demonstrations; specific recurring contract values and customer concentration not verified. | E29: Existing sensor products offer a nearer revenue path than a wholly new SoC. Verify field calibration, certifications and customer renewals. | F29: University of Cambridge technology licensing and IIT Bombay fabrication collaboration; not a global chipmaker offtake. | G29: Reliance Industries, L&T, NTPC, Indian Oil, GAIL and industrial gas/equipment companies are prospective users. | H29: Potential packaging/test demand for Kaynes, CG Semi, Suchi or Tata’s packaging business after package qualification. A future Tata silicon-fab port needs compatible node, process IP and redesign; no automatic fit. | I29: S081, S082, S083, S084, S001
